Workbook

Sheet Rekap
A2: Posisi Gangguan | B2: Jarak Antar Titik Terluar Quadrotor | D2: Simpangan Maksimum | E2: Posisi Gangguan | F2: Jarak Antar Titik Terluar Quadrotor | H2: Simpangan Maksimum
A3: Kiri | B3: 20 cm | C3: Percobaan 1 | D3: ='20'!G2 -> 100.66667 | E3: Kanan | F3: 20 cm | G3: Percobaan 1 | H3: ='20'!AG2 -> 106.66667
C4: Percobaan 2 | D4: ='20'!H2 -> 99.666667 | G4: Percobaan 2 | H4: ='20'!AH2 -> 102.66667
C5: Percobaan 3 | D5: ='20'!I2 -> 98.666667 | G5: Percobaan 3 | H5: ='20'!AI2 -> 106.66667
B6: Rata-rata | D6: =AVERAGE(D3:D5) -> 99.666667 | F6: Rata-rata | H6: =AVERAGE(H3:H5) -> 105.33333
B7: 30 cm | C7: Percobaan 1 | D7: ='30'!G2 -> 90.666667 | F7: 30 cm | G7: Percobaan 1 | H7: ='30'!AG2 -> 89.333333
C8: Percobaan 2 | D8: ='30'!H2 -> 92.666667 | G8: Percobaan 2 | H8: ='30'!AH2 -> 92.333333
C9: Percobaan 3 | D9: ='30'!I2 -> 95.666667 | G9: Percobaan 3 | H9: ='30'!AI2 -> 93.333333
B10: Rata-rata | D10: =AVERAGE(D7:D9) -> 93 | F10: Rata-rata | H10: =AVERAGE(H7:H9) -> 91.666667
B11: 40 cm | C11: Percobaan 1 | D11: ='40'!G2 -> 71 | F11: 40 cm | G11: Percobaan 1 | H11: ='40'!AG2 -> 73.333333
C12: Percobaan 2 | D12: ='40'!H2 -> 68 | G12: Percobaan 2 | H12: ='40'!AH2 -> 75.333333
C13: Percobaan 3 | D13: ='40'!I2 -> 72 | G13: Percobaan 3 | H13: ='40'!AI2 -> 71.333333
B14: Rata-rata | D14: =AVERAGE(D11:D13) -> 70.333333 | F14: Rata-rata | H14: =AVERAGE(H11:H13) -> 73.333333
B15: 50 cm | C15: Percobaan 1 | D15: ='50'!G2 -> 58.333333 | F15: 50 cm | G15: Percobaan 1 | H15: ='50'!AG2 -> 63.333333
C16: Percobaan 2 | D16: ='50'!H2 -> 58.333333 | G16: Percobaan 2 | H16: ='50'!AH2 -> 64.333333
C17: Percobaan 3 | D17: ='50'!I2 -> 60.333333 | G17: Percobaan 3 | H17: ='50'!AI2 -> 58.333333
B18: Rata-rata | D18: =AVERAGE(D15:D17) -> 59 | F18: Rata-rata | H18: =AVERAGE(H15:H17) -> 62
B19: 60 cm | C19: Percobaan 1 | D19: ='60'!G2 -> 37.333333 | F19: 60 cm | G19: Percobaan 1 | H19: ='60'!AG2 -> 41
C20: Percobaan 2 | D20: ='60'!H2 -> 36.333333 | G20: Percobaan 2 | H20: ='60'!AH2 -> 40
C21: Percobaan 3 | D21: ='60'!I2 -> 35.333333 | G21: Percobaan 3 | H21: ='60'!AI2 -> 40
B22: Rata-rata | D22: =AVERAGE(D19:D21) -> 36.333333 | F22: Rata-rata | H22: =AVERAGE(H19:H21) -> 40.333333
B23: 70 cm | C23: Percobaan 1 | D23: ='70'!G2 -> 14.666667 | F23: 70 cm | G23: Percobaan 1 | H23: ='70'!AG2 -> 22.666667
C24: Percobaan 2 | D24: ='70'!H2 -> 14.666667 | G24: Percobaan 2 | H24: ='70'!AH2 -> 25.666667
C25: Percobaan 3 | D25: ='70'!I2 -> 13.666667 | G25: Percobaan 3 | H25: ='70'!AI2 -> 21.666667
B26: Rata-rata | D26: =AVERAGE(D23:D25) -> 14.333333 | F26: Rata-rata | H26: =AVERAGE(H23:H25) -> 23.333333
B27: 80 cm | C27: Percobaan 1 | D27: ='80'!G2 -> 5.3333333 | F27: 80 cm | G27: Percobaan 1 | H27: ='80'!AG2 -> 14
C28: Percobaan 2 | D28: ='80'!H2 -> 8.3333333 | G28: Percobaan 2 | H28: ='80'!AH2 -> 15
C29: Percobaan 3 | D29: ='80'!I2 -> 8.3333333 | G29: Percobaan 3 | H29: ='80'!AI2 -> 15
B30: Rata-rata | D30: =AVERAGE(D27:D29) -> 7.3333333 | F30: Rata-rata | H30: =AVERAGE(H27:H29) -> 14.666667
B31: 90 cm | C31: Percobaan 1 | D31: ='90'!G2 -> 2 | F31: 90 cm | G31: Percobaan 1 | H31: ='90'!AG2 -> 4.6666667
C32: Percobaan 2 | D32: ='90'!H2 -> 4 | G32: Percobaan 2 | H32: ='90'!AH2 -> 4.6666667
C33: Percobaan 3 | D33: ='90'!I2 -> 3 | G33: Percobaan 3 | H33: ='90'!AI2 -> 4.6666667
B34: Rata-rata | D34: =AVERAGE(D31:D33) -> 3 | F34: Rata-rata | H34: =AVERAGE(H31:H33) -> 4.6666667
B35: 100 cm | C35: Percobaan 1 | D35: ='100'!G2 -> 2.6666667 | F35: 100 cm | G35: Percobaan 1 | H35: ='100'!AG2 -> 3.6666667
C36: Percobaan 2 | D36: ='100'!H2 -> 7.6666667 | G36: Percobaan 2 | H36: ='100'!AH2 -> 8.6666667
C37: Percobaan 3 | D37: ='100'!I2 -> 3.6666667 | G37: Percobaan 3 | H37: ='100'!AI2 -> 5.6666667
B38: Rata-rata | D38: =AVERAGE(D35:D37) -> 4.6666667 | F38: Rata-rata | H38: =AVERAGE(H35:H37) -> 6

Sheet Sheet21
A3: Jarak Antar Titik Terluar Quadrotor (cm) | B3: Jarak Antar Pusat Quadrotor (cm) | C3: Parameter Kontrol | D3: RMSE X (cm) | E3: RMSE Y (cm) | F3: Overshoot Maksimum X (cm) | G3: Overshoot Maksimum Y (cm) | K3: Jarak Antar Titik Terluar Quadrotor (cm) | L3: Jarak Antar Pusat Quadrotor (cm) | M3: Parameter Kontrol | N3: RMSE X (cm) | O3: RMSE Y (cm) | P3: Overshoot Maksimum X (cm) | Q3: Overshoot Maksimum Y (cm)
A4: 20 | B4: 80 | C4: Penalaan Manual | D4: Quadrotor utama menabrak Quadrotor Gangguan | K4: 20 | L4: 80 | M4: Penalaan Manual | N4: Quadrotor utama menabrak Quadrotor Gangguan
C6: Setelah Optimasi | M6: Setelah Optimasi
A8: 30 | B8: 90 | C8: Penalaan Manual | D8: Quadrotor utama menabrak Quadrotor Gangguan | K8: 30 | L8: 90 | M8: Penalaan Manual | N8: Quadrotor utama menabrak Quadrotor Gangguan
C10: Setelah Optimasi | D10: 12.444 | E10: 13.439 | F10: 29.021 | G10: 27.497 | M10: Setelah Optimasi | N10: 13.76 | O10: 12.077 | P10: 28.751 | Q10: 27.269
D11: 14.076 | E11: 12.182 | F11: 30.791 | G11: 27.595 | N11: 14.102 | O11: 12.248 | P11: 30.753 | Q11: 28.628
A12: 50 | B12: 110 | C12: Penalaan Manual | D12: 21.51 | E12: 20.148 | F12: 48.666 | G12: 46.993 | K12: 50 | L12: 110 | M12: Penalaan Manual | N12: 22.521 | O12: 21.018 | P12: 48.709 | Q12: 47.582
D13: 22.471 | E13: 19.113 | F13: 46.212 | G13: 45.69 | N13: 23.237 | O13: 19.601 | P13: 47.329 | Q13: 44.818
C14: Setelah Optimasi | D14: 12.153 | E14: 11.072 | F14: 27.382 | G14: 26.667 | M14: Setelah Optimasi | N14: 13.235 | O14: 12.872 | P14: 27.732 | Q14: 26.883
D15: 12.265 | E15: 12.09 | F15: 24.151 | G15: 24.265 | N15: 12.81 | O15: 12.608 | P15: 23.791 | Q15: 24.927
A16: 80 | B16: 140 | C16: Penalaan Manual | D16: 22.159 | E16: 20.815 | F16: 48.569 | G16: 45.147 | K16: 80 | L16: 140 | M16: Penalaan Manual | N16: 22.335 | O16: 19.493 | P16: 48.699 | Q16: 45.917
D17: 21.509 | E17: 19.453 | F17: 49.046 | G17: 47.16 | N17: 21.81 | O17: 19.445 | P17: 49.166 | Q17: 47.373
C18: Setelah Optimasi | D18: 12.652 | E18: 11.379 | F18: 24.852 | G18: 24.155 | M18: Setelah Optimasi | N18: 11.338 | O18: 11.383 | P18: 24.749 | Q18: 24.249
D19: 12.971 | E19: 11.658 | F19: 25.926 | G19: 24.19 | N19: 12.297 | O19: 10.605 | P19: 26.366 | Q19: 25.209
A20: 100 | B20: 160 | C20: Penalaan Manual | D20: 21.56 | E20: 17.239 | F20: 46.493 | G20: 45.517 | K20: 100 | L20: 160 | M20: Penalaan Manual | N20: 21.057 | O20: 17.825 | P20: 46.455 | Q20: 45.467
D21: 21.542 | E21: 19.126 | F21: 48.505 | G21: 46.261 | N21: 21.108 | O21: 19.56 | P21: 47.09 | Q21: 46.062
C22: Setelah Optimasi | D22: 11.057 | E22: 10.852 | F22: 29.09 | G22: 27.551 | M22: Setelah Optimasi | N22: 12.208 | O22: 10.582 | P22: 29.37 | Q22: 27.336
D23: 11.368 | E23: 11.629 | F23: 26.884 | G23: 26.589 | N23: 12.209 | O23: 11.525 | P23: 26.215 | Q23: 26.41
A24: Rata-rata penalaan manual | D24: 21.679167 | E24: 19.822167 | F24: 47.785667 | G24: 45.751833 | K24: Rata-rata penalaan manual | N24: 22.011333 | O24: 19.490333 | P24: 47.908 | Q24: 46.203167
A25: Rata-rata setelah optimasi | D25: 12.78675 | E25: 12.135875 | F25: 27.266625 | G25: 25.597125 | K25: Rata-rata setelah optimasi | N25: 12.744875 | O25: 11.7375 | P25: 27.215875 | Q25: 26.363875

Sheet 20
G1: Max1 | H1: Max2 | I1: Max 3 | J1: Kiri | T1: Kanan | AG1: Max1 | AH1: Max2 | AI1: Max 3
G2: =MAX(G4:G485) -> 100.66667 | H2: =MAX(H4:H485) -> 99.666667 | I2: =MAX(I4:I485) -> 98.666667 | AG2: =MAX(AG4:AG485) -> 106.66667 | AH2: =MAX(AH4:AH485) -> 102.66667 | AI2: =MAX(AI4:AI485) -> 106.66667
B3: t | C3: gangg x | D3: gangg y | E3: Ux | F3: Uy | G3: Simpangan 1 | H3: Simpangan 2 | I3: Simpangan 3 | J3: x | K3: y | T3: x | U3: y | AC3: gangg x | AD3: gangg y | AE3: Ux | AF3: Uy | AG3: Simpangan 1 | AH3: Simpangan 2 | AI3: Simpangan 3
A4: 1 | B4: =A4*0.03 -> 0.03 | C4: =50 -> 50 | D4: 300 | E4: =AVERAGE(J4,M4,P4) -> 134.33333 | F4: =MIN(K4,N4,Q4) -> 44.600006 | G4: =J4-E4 -> -1.3333333 | H4: =M4-E4 -> -1.3333333 | I4: =P4-E4 -> 2.6666667 | J4: 133 | K4: 44.600006 | M4: 133 | N4: 48.600006 | P4: 137 | Q4: 48.600006 | T4: 270 | U4: 38.600006 | W4: 276 | X4: 37.600006 | Z4: 275 | AA4: 38.600006 | AB4: c | AC4: =350 -> 350 | AD4: 350 | AE4: =AVERAGE(T4,W4,Z4) -> 273.66667 | AF4: =MIN(U4,X4,AA4) -> 37.600006 | AG4: =AE4-T4 -> 3.6666667 | AH4: =AE4-W4 -> -2.3333333 | AI4: =AE4-Z4 -> -1.3333333
A5: 2 | B5: =A5*0.03 -> 0.06 | C5: =C4 -> 50 | D5: =D4 -> 300 | E5: =E4 -> 134.33333 | F5: =F4+1 -> 45.600006 | G5: =J5-E5 -> -1.3333333 | H5: =M5-E5 -> -1.3333333 | I5: =P5-E5 -> 1.6666667 | J5: 133 | K5: 45.600006 | M5: 133 | N5: 49.600006 | P5: 136 | Q5: 49.600006 | T5: 270 | U5: 39.600006 | W5: 276 | X5: 38.600006 | Z5: 275 | AA5: 40.600006 | AB5: c | AC5: =AC4 -> 350 | AD5: =AD4 -> 350 | AE5: =AE4 -> 273.66667 | AF5: =AF4+2 -> 39.600006 | AG5: =AE5-T5 -> 3.6666667 | AH5: =AE5-W5 -> -2.3333333 | AI5: =AE5-Z5 -> -1.3333333
A6: 3 | B6: =A6*0.03 -> 0.09 | C6: =C5 -> 50 | D6: =D5 -> 300 | E6: =E5 -> 134.33333 | F6: =F5+1 -> 46.600006 | G6: =J6-E6 -> -1.3333333 | H6: =M6-E6 -> -1.3333333 | I6: =P6-E6 -> 0.66666667 | J6: 133 | K6: 45.600006 | M6: 133 | N6: 49.600006 | P6: 135 | Q6: 51.600006 | T6: 270 | U6: 41.600006 | W6: 275 | X6: 40.600006 | Z6: 276 | AA6: 41.600006 | AB6: c | AC6: =AC5 -> 350 | AD6: =AD5 -> 350 | AE6: =AE5 -> 273.66667 | AF6: =AF5+2 -> 41.600006 | AG6: =AE6-T6 -> 3.6666667 | AH6: =AE6-W6 -> -1.3333333 | AI6: =AE6-Z6 -> -2.3333333
A7: 4 | B7: =A7*0.03 -> 0.12 | C7: =C6 -> 50 | D7: =D6 -> 300 | E7: =E6 -> 134.33333 | F7: =F6+1 -> 47.600006 | G7: =J7-E7 -> -1.3333333 | H7: =M7-E7 -> -1.3333333 | I7: =P7-E7 -> -4.3333333 | J7: 133 | K7: 46.600006 | M7: 133 | N7: 50.600006 | P7: 130 | Q7: 58.600006 | T7: 270 | U7: 42.600006 | W7: 275 | X7: 42.600006 | Z7: 276 | AA7: 42.600006 | AB7: c | AC7: =AC6 -> 350 | AD7: =AD6 -> 350 | AE7: =AE6 -> 273.66667 | AF7: =AF6+2 -> 43.600006 | AG7: =AE7-T7 -> 3.6666667 | AH7: =AE7-W7 -> -1.3333333 | AI7: =AE7-Z7 -> -2.3333333
A8: 5 | B8: =A8*0.03 -> 0.15 | C8: =C7 -> 50 | D8: =D7 -> 300 | E8: =E7 -> 134.33333 | F8: =F7+1 -> 48.600006 | G8: =J8-E8 -> -1.3333333 | H8: =M8-E8 -> -1.3333333 | I8: =P8-E8 -> -5.3333333 | J8: 133 | K8: 47.600006 | M8: 133 | N8: 51.600006 | P8: 129 | Q8: 59.600006 | T8: 270 | U8: 44.600006 | W8: 274 | X8: 43.600006 | Z8: 276 | AA8: 44.600006 | AB8: c | AC8: =AC7 -> 350 | AD8: =AD7 -> 350 | AE8: =AE7 -> 273.66667 | AF8: =AF7+2 -> 45.600006 | AG8: =AE8-T8 -> 3.6666667 | AH8: =AE8-W8 -> -0.33333333 | AI8: =AE8-Z8 -> -2.3333333
A9: 6 | B9: =A9*0.03 -> 0.18 | C9: =C8 -> 50 | D9: =D8 -> 300 | E9: =E8 -> 134.33333 | F9: =F8+1 -> 49.600006 | G9: =J9-E9 -> -1.3333333 | H9: =M9-E9 -> -1.3333333 | I9: =P9-E9 -> -5.3333333 | J9: 133 | K9: 48.600006 | M9: 133 | N9: 52.600006 | P9: 129 | Q9: 59.600006 | T9: 270 | U9: 45.600006 | W9: 274 | X9: 44.600006 | Z9: 277 | AA9: 45.600006 | AB9: c | AC9: =AC8 -> 350 | AD9: =AD8 -> 350 | AE9: =AE8 -> 273.66667 | AF9: =AF8+2 -> 47.600006 | AG9: =AE9-T9 -> 3.6666667 | AH9: =AE9-W9 -> -0.33333333 | AI9: =AE9-Z9 -> -3.3333333
A10: 7 | B10: =A10*0.03 -> 0.21 | C10: =C9 -> 50 | D10: =D9 -> 300 | E10: =E9 -> 134.33333 | F10: =F9+1 -> 50.600006 | G10: =J10-E10 -> -1.3333333 | H10: =M10-E10 -> -1.3333333 | I10: =P10-E10 -> -5.3333333 | J10: 133 | K10: 49.600006 | M10: 133 | N10: 53.600006 | P10: 129 | Q10: 60.600006 | T10: 269 | U10: 45.600006 | W10: 273 | X10: 46.600006 | Z10: 277 | AA10: 45.600006 | AB10: c | AC10: =AC9 -> 350 | AD10: =AD9 -> 350 | AE10: =AE9 -> 273.66667 | AF10: =AF9+2 -> 49.600006 | AG10: =AE10-T10 -> 4.6666667 | AH10: =AE10-W10 -> 0.66666667 | AI10: =AE10-Z10 -> -3.3333333
A11: 8 | B11: =A11*0.03 -> 0.24 | C11: =C10 -> 50 | D11: =D10 -> 300 | E11: =E10 -> 134.33333 | F11: =F10+1 -> 51.600006 | G11: =J11-E11 -> -1.3333333 | H11: =M11-E11 -> -1.3333333 | I11: =P11-E11 -> -5.3333333 | J11: 133 | K11: 49.600006 | M11: 133 | N11: 53.600006 | P11: 129 | Q11: 61.600006 | T11: 269 | U11: 45.600006 | W11: 273 | X11: 47.600006 | Z11: 277 | AA11: 46.600006 | AB11: c | AC11: =AC10 -> 350 | AD11: =AD10 -> 350 | AE11: =AE10 -> 273.66667 | AF11: =AF10+2 -> 51.600006 | AG11: =AE11-T11 -> 4.6666667 | AH11: =AE11-W11 -> 0.66666667 | AI11: =AE11-Z11 -> -3.3333333
A12: 9 | B12: =A12*0.03 -> 0.27 | C12: =C11 -> 50 | D12: =D11 -> 300 | E12: =E11 -> 134.33333 | F12: =F11+1 -> 52.600006 | G12: =J12-E12 -> -1.3333333 | H12: =M12-E12 -> -1.3333333 | I12: =P12-E12 -> -6.3333333 | J12: 133 | K12: 50.600006 | M12: 133 | N12: 54.600006 | P12: 128 | Q12: 61.600006 | T12: 269 | U12: 46.600006 | W12: 273 | X12: 49.600006 | Z12: 277 | AA12: 47.600006 | AB12: c | AC12: =AC11 -> 350 | AD12: =AD11 -> 350 | AE12: =AE11 -> 273.66667 | AF12: =AF11+2 -> 53.600006 | AG12: =AE12-T12 -> 4.6666667 | AH12: =AE12-W12 -> 0.66666667 | AI12: =AE12-Z12 -> -3.3333333
A13: 10 | B13: =A13*0.03 -> 0.3 | C13: =C12 -> 50 | D13: =D12 -> 300 | E13: =E12 -> 134.33333 | F13: =F12+1 -> 53.600006 | G13: =J13-E13 -> -1.3333333 | H13: =M13-E13 -> -1.3333333 | I13: =P13-E13 -> -6.3333333 | J13: 133 | K13: 51.600006 | M13: 133 | N13: 55.600006 | P13: 128 | Q13: 61.600006 | T13: 269 | U13: 47.600006 | W13: 273 | X13: 49.600006 | Z13: 277 | AA13: 48.600006 | AB13: c | AC13: =AC12 -> 350 | AD13: =AD12 -> 350 | AE13: =AE12 -> 273.66667 | AF13: =AF12+2 -> 55.600006 | AG13: =AE13-T13 -> 4.6666667 | AH13: =AE13-W13 -> 0.66666667 | AI13: =AE13-Z13 -> -3.3333333
A14: 11 | B14: =A14*0.03 -> 0.33 | C14: =C13 -> 50 | D14: =D13 -> 300 | E14: =E13 -> 134.33333 | F14: =F13+1 -> 54.600006 | G14: =J14-E14 -> -1.3333333 | H14: =M14-E14 -> -1.3333333 | I14: =P14-E14 -> -6.3333333 | J14: 133 | K14: 52.600006 | M14: 133 | N14: 56.600006 | P14: 128 | Q14: 62.600006 | T14: 269 | U14: 48.600006 | W14: 273 | X14: 50.600006 | Z14: 277 | AA14: 49.600006 | AB14: c | AC14: =AC13 -> 350 | AD14: =AD13 -> 350 | AE14: =AE13 -> 273.66667 | AF14: =AF13+2 -> 57.600006 | AG14: =AE14-T14 -> 4.6666667 | AH14: =AE14-W14 -> 0.66666667 | AI14: =AE14-Z14 -> -3.3333333
A15: 12 | B15: =A15*0.03 -> 0.36 | C15: =C14 -> 50 | D15: =D14 -> 300 | E15: =E14 -> 134.33333 | F15: =F14+1 -> 55.600006 | G15: =J15-E15 -> -1.3333333 | H15: =M15-E15 -> -1.3333333 | I15: =P15-E15 -> -7.3333333 | J15: 133 | K15: 53.600006 | M15: 133 | N15: 57.600006 | P15: 127 | Q15: 63.600006 | T15: 269 | U15: 49.600006 | W15: 273 | X15: 52.600006 | Z15: 278 | AA15: 50.600006 | AB15: c | AC15: =AC14 -> 350 | AD15: =AD14 -> 350 | AE15: =AE14 -> 273.66667 | AF15: =AF14+2 -> 59.600006 | AG15: =AE15-T15 -> 4.6666667 | AH15: =AE15-W15 -> 0.66666667 | AI15: =AE15-Z15 -> -4.3333333
A16: 13 | B16: =A16*0.03 -> 0.39 | C16: =C15 -> 50 | D16: =D15 -> 300 | E16: =E15 -> 134.33333 | F16: =F15+1 -> 56.600006 | G16: =J16-E16 -> -1.3333333 | H16: =M16-E16 -> -1.3333333 | I16: =P16-E16 -> -7.3333333 | J16: 133 | K16: 53.600006 | M16: 133 | N16: 57.600006 | P16: 127 | Q16: 64.600006 | T16: 269 | U16: 49.600006 | W16: 273 | X16: 53.600006 | Z16: 279 | AA16: 52.600006 | AB16: c | AC16: =AC15 -> 350 | AD16: =AD15 -> 350 | AE16: =AE15 -> 273.66667 | AF16: =AF15+2 -> 61.600006 | AG16: =AE16-T16 -> 4.6666667 | AH16: =AE16-W16 -> 0.66666667 | AI16: =AE16-Z16 -> -5.3333333
... A351: 348 | B351: =A351*0.03 -> 10.44 | C351: =C350 -> 50 | D351: =D350 -> 300 | E351: =E350 -> 134.33333 | F351: =F350+1 -> 391.60001 | G351: =J351-E351 -> 94.666667 | H351: =M351-E351 -> 94.666667 | I351: =P351-E351 -> 86.666667 | J351: 229 | K351: 376.60001 | M351: 229 | N351: 476.6 | P351: 221 | Q351: 377.60001 | T351: 172 | U351: 437.6 | W351: 172 | X351: 442.6 | Z351: 167 | AA351: 405.60001 | AB351: c | AC351: =AC350 -> 350 | AD351: =AD350 -> 350 | AE351: =AE350 -> 273.66667 | AF351: =AF350+2 -> 731.60001 | AG351: =AE351-T351 -> 101.66667 | AH351: =AE351-W351 -> 101.66667 | AI351: =AE351-Z351 -> 106.66667
A352: 349 | B352: =A352*0.03 -> 10.47 | C352: =C351 -> 50 | D352: =D351 -> 300 | E352: =E351 -> 134.33333 | F352: =F351+1 -> 392.60001 | G352: =J352-E352 -> 94.666667 | I352: =P352-E352 -> 86.666667 | J352: 229 | K352: 377.60001 | P352: 221 | Q352: 378.60001 | T352: 172 | U352: 438.6 | W352: 172 | X352: 443.6 | Z352: 167 | AA352: 407.60001 | AB352: c | AC352: =AC351 -> 350 | AD352: =AD351 -> 350 | AE352: =AE351 -> 273.66667 | AF352: =AF351+2 -> 733.60001 | AG352: =AE352-T352 -> 101.66667 | AH352: =AE352-W352 -> 101.66667 | AI352: =AE352-Z352 -> 106.66667
A353: 350 | B353: =A353*0.03 -> 10.5 | C353: =C352 -> 50 | D353: =D352 -> 300 | E353: =E352 -> 134.33333 | F353: =F352+1 -> 393.60001 | G353: =J353-E353 -> 94.666667 | I353: =P353-E353 -> 86.666667 | J353: 229 | K353: 379.60001 | P353: 221 | Q353: 379.60001 | T353: 172 | U353: 441.6 | W353: 172 | X353: 444.6 | Z353: 167 | AA353: 408.60001 | AB353: c | AC353: =AC352 -> 350 | AD353: =AD352 -> 350 | AE353: =AE352 -> 273.66667 | AF353: =AF352+2 -> 735.60001 | AG353: =AE353-T353 -> 101.66667 | AH353: =AE353-W353 -> 101.66667 | AI353: =AE353-Z353 -> 106.66667
A354: 351 | B354: =A354*0.03 -> 10.53 | C354: =C353 -> 50 | D354: =D353 -> 300 | E354: =E353 -> 134.33333 | F354: =F353+1 -> 394.60001 | G354: =J354-E354 -> 94.666667 | I354: =P354-E354 -> 86.666667 | J354: 229 | K354: 380.60001 | P354: 221 | Q354: 380.60001 | T354: 172 | U354: 445.6 | W354: 172 | X354: 445.6 | Z354: 167 | AA354: 409.60001 | AB354: c | AC354: =AC353 -> 350 | AD354: =AD353 -> 350 | AE354: =AE353 -> 273.66667 | AF354: =AF353+2 -> 737.60001 | AG354: =AE354-T354 -> 101.66667 | AH354: =AE354-W354 -> 101.66667 | AI354: =AE354-Z354 -> 106.66667
A355: 352 | B355: =A355*0.03 -> 10.56 | C355: =C354 -> 50 | D355: =D354 -> 300 | E355: =E354 -> 134.33333 | F355: =F354+1 -> 395.60001 | G355: =J355-E355 -> 94.666667 | I355: =P355-E355 -> 86.666667 | J355: 229 | K355: 382.60001 | P355: 221 | Q355: 381.60001 | T355: 172 | U355: 447.6 | W355: 172 | X355: 445.6 | Z355: 167 | AA355: 411.60001 | AB355: c | AC355: =AC354 -> 350 | AD355: =AD354 -> 350 | AE355: =AE354 -> 273.66667 | AF355: =AF354+2 -> 739.60001 | AG355: =AE355-T355 -> 101.66667 | AH355: =AE355-W355 -> 101.66667 | AI355: =AE355-Z355 -> 106.66667
A356: 353 | B356: =A356*0.03 -> 10.59 | C356: =C355 -> 50 | D356: =D355 -> 300 | E356: =E355 -> 134.33333 | F356: =F355+1 -> 396.60001 | G356: =J356-E356 -> 94.666667 | I356: =P356-E356 -> 86.666667 | J356: 229 | K356: 383.60001 | P356: 221 | Q356: 381.60001 | T356: 172 | U356: 449.6 | W356: 172 | X356: 446.6 | Z356: 167 | AA356: 413.60001 | AB356: c | AC356: =AC355 -> 350 | AD356: =AD355 -> 350 | AE356: =AE355 -> 273.66667 | AF356: =AF355+2 -> 741.60001 | AG356: =AE356-T356 -> 101.66667 | AH356: =AE356-W356 -> 101.66667 | AI356: =AE356-Z356 -> 106.66667
A357: 354 | B357: =A357*0.03 -> 10.62 | C357: =C356 -> 50 | D357: =D356 -> 300 | E357: =E356 -> 134.33333 | F357: =F356+1 -> 397.60001 | G357: =J357-E357 -> 94.666667 | I357: =P357-E357 -> 86.666667 | J357: 229 | K357: 384.60001 | P357: 221 | Q357: 382.60001 | T357: 172 | U357: 450.6 | W357: 173 | X357: 447.6 | Z357: 167 | AA357: 414.60001 | AB357: c | AC357: =AC356 -> 350 | AD357: =AD356 -> 350 | AE357: =AE356 -> 273.66667 | AF357: =AF356+2 -> 743.60001 | AG357: =AE357-T357 -> 101.66667 | AH357: =AE357-W357 -> 100.66667 | AI357: =AE357-Z357 -> 106.66667
A358: 355 | B358: =A358*0.03 -> 10.65 | C358: =C357 -> 50 | D358: =D357 -> 300 | E358: =E357 -> 134.33333 | F358: =F357+1 -> 398.60001 | G358: =J358-E358 -> 94.666667 | I358: =P358-E358 -> 85.666667 | J358: 229 | K358: 385.60001 | P358: 220 | Q358: 383.60001 | T358: 172 | U358: 452.6 | W358: 173 | X358: 448.6 | Z358: 167 | AA358: 416.60001 | AB358: c | AC358: =AC357 -> 350 | AD358: =AD357 -> 350 | AE358: =AE357 -> 273.66667 | AF358: =AF357+2 -> 745.60001 | AG358: =AE358-T358 -> 101.66667 | AH358: =AE358-W358 -> 100.66667 | AI358: =AE358-Z358 -> 106.66667
A359: 356 | B359: =A359*0.03 -> 10.68 | C359: =C358 -> 50 | D359: =D358 -> 300 | E359: =E358 -> 134.33333 | F359: =F358+1 -> 399.60001 | G359: =J359-E359 -> 94.666667 | I359: =P359-E359 -> 85.666667 | J359: 229 | K359: 387.60001 | P359: 220 | Q359: 384.60001 | T359: 172 | U359: 453.6 | W359: 173 | X359: 449.6 | Z359: 167 | AA359: 417.60001 | AB359: c | AC359: =AC358 -> 350 | AD359: =AD358 -> 350 | AE359: =AE358 -> 273.66667 | AF359: =AF358+2 -> 747.60001 | AG359: =AE359-T359 -> 101.66667 | AH359: =AE359-W359 -> 100.66667 | AI359: =AE359-Z359 -> 106.66667
A360: 357 | B360: =A360*0.03 -> 10.71 | C360: =C359 -> 50 | D360: =D359 -> 300 | E360: =E359 -> 134.33333 | F360: =F359+1 -> 400.60001 | G360: =J360-E360 -> 95.666667 | I360: =P360-E360 -> 85.666667 | J360: 230 | K360: 388.60001 | P360: 220 | Q360: 385.60001 | T360: 172 | U360: 453.6 | W360: 173 | X360: 449.6 | Z360: 167 | AA360: 418.60001 | AB360: c | AC360: =AC359 -> 350 | AD360: =AD359 -> 350 | AE360: =AE359 -> 273.66667 | AF360: =AF359+2 -> 749.60001 | AG360: =AE360-T360 -> 101.66667 | AH360: =AE360-W360 -> 100.66667 | AI360: =AE360-Z360 -> 106.66667
A361: 358 | B361: =A361*0.03 -> 10.74 | C361: =C360 -> 50 | D361: =D360 -> 300 | E361: =E360 -> 134.33333 | F361: =F360+1 -> 401.60001 | G361: =J361-E361 -> 95.666667 | I361: =P361-E361 -> 84.666667 | J361: 230 | K361: 389.60001 | P361: 219 | Q361: 385.60001 | T361: 172 | U361: 454.6 | W361: 173 | X361: 450.6 | Z361: 167 | AA361: 419.60001 | AB361: c | AC361: =AC360 -> 350 | AD361: =AD360 -> 350 | AE361: =AE360 -> 273.66667 | AF361: =AF360+2 -> 751.60001 | AG361: =AE361-T361 -> 101.66667 | AH361: =AE361-W361 -> 100.66667 | AI361: =AE361-Z361 -> 106.66667
A362: 359 | B362: =A362*0.03 -> 10.77 | C362: =C361 -> 50 | D362: =D361 -> 300 | E362: =E361 -> 134.33333 | F362: =F361+1 -> 402.60001 | G362: =J362-E362 -> 95.666667 | I362: =P362-E362 -> 84.666667 | J362: 230 | K362: 390.60001 | P362: 219 | Q362: 386.60001 | T362: 172 | U362: 455.6 | W362: 173 | X362: 451.6 | Z362: 167 | AA362: 421.60001 | AC362: =AC361 -> 350 | AD362: =AD361 -> 350 | AE362: =AE361 -> 273.66667 | AF362: =AF361+2 -> 753.60001 | AG362: =AE362-T362 -> 101.66667 | AH362: =AE362-W362 -> 100.66667
A363: 360 | B363: =A363*0.03 -> 10.8 | C363: =C362 -> 50 | D363: =D362 -> 300 | E363: =E362 -> 134.33333 | F363: =F362+1 -> 403.60001 | G363: =J363-E363 -> 95.666667 | I363: =P363-E363 -> 84.666667 | J363: 230 | K363: 391.60001 | P363: 219 | Q363: 387.60001 | T363: 172 | U363: 456.6 | W363: 174 | X363: 453.6 | Z363: 167 | AA363: 421.60001 | AC363: =AC362 -> 350 | AD363: =AD362 -> 350 | AE363: =AE362 -> 273.66667 | AF363: =AF362+2 -> 755.60001 | AG363: =AE363-T363 -> 101.66667 | AH363: =AE363-W363 -> 99.666667
A364: 361 | B364: =A364*0.03 -> 10.83 | C364: =C363 -> 50 | D364: =D363 -> 300 | E364: =E363 -> 134.33333 | F364: =F363+1 -> 404.60001 | G364: =J364-E364 -> 95.666667 | I364: =P364-E364 -> 83.666667 | J364: 230 | K364: 392.60001 | P364: 218 | Q364: 388.60001 | T364: 172 | U364: 457.6 | W364: 174 | X364: 453.6 | Z364: 167 | AA364: 422.60001 | AC364: =AC363 -> 350 | AD364: =AD363 -> 350 | AE364: =AE363 -> 273.66667 | AF364: =AF363+2 -> 757.60001 | AG364: =AE364-T364 -> 101.66667 | AH364: =AE364-W364 -> 99.666667
A365: 362 | B365: =A365*0.03 -> 10.86 | C365: =C364 -> 50 | D365: =D364 -> 300 | E365: =E364 -> 134.33333 | F365: =F364+1 -> 405.60001 | G365: =J365-E365 -> 96.666667 | I365: =P365-E365 -> 83.666667 | J365: 231 | K365: 393.60001 | P365: 218 | Q365: 389.60001 | T365: 172 | U365: 457.6 | W365: 174 | X365: 454.6 | Z365: 167 | AA365: 425.60001 | AC365: =AC364 -> 350 | AD365: =AD364 -> 350 | AE365: =AE364 -> 273.66667 | AF365: =AF364+2 -> 759.60001 | AG365: =AE365-T365 -> 101.66667 | AH365: =AE365-W365 -> 99.666667
A366: 363 | B366: =A366*0.03 -> 10.89 | C366: =C365 -> 50 | D366: =D365 -> 300 | E366: =E365 -> 134.33333 | F366: =F365+1 -> 406.60001 | G366: =J366-E366 -> 96.666667 | I366: =P366-E366 -> 83.666667 | J366: 231 | K366: 395.60001 | P366: 218 | Q366: 390.60001 | T366: 172 | U366: 458.6 | W366: 175 | X366: 456.6 | Z366: 167 | AA366: 425.60001 | AC366: =AC365 -> 350 | AD366: =AD365 -> 350 | AE366: =AE365 -> 273.66667 | AF366: =AF365+2 -> 761.60001 | AG366: =AE366-T366 -> 101.66667 | AH366: =AE366-W366 -> 98.666667
A367: 364 | B367: =A367*0.03 -> 10.92 | C367: =C366 -> 50 | D367: =D366 -> 300 | E367: =E366 -> 134.33333 | F367: =F366+1 -> 407.60001 | G367: =J367-E367 -> 96.666667 | I367: =P367-E367 -> 83.666667 | J367: 231 | K367: 396.60001 | P367: 218 | Q367: 391.60001 | T367: 172 | U367: 459.6 | W367: 175 | X367: 457.6 | Z367: 167 | AA367: 426.60001 | AC367: =AC366 -> 350 | AD367: =AD366 -> 350 | AE367: =AE366 -> 273.66667 | AF367: =AF366+2 -> 763.60001 | AH367: =AE367-W367 -> 98.666667
A368: 365 | B368: =A368*0.03 -> 10.95 | C368: =C367 -> 50 | D368: =D367 -> 300 | E368: =E367 -> 134.33333 | F368: =F367+1 -> 408.60001 | G368: =J368-E368 -> 97.666667 | J368: 232 | K368: 397.60001 | P368: 218 | Q368: 393.60001 | T368: 172 | U368: 460.6 | W368: 176 | X368: 457.6 | Z368: 167 | AA368: 427.60001 | AC368: =AC367 -> 350 | AD368: =AD367 -> 350 | AE368: =AE367 -> 273.66667 | AF368: =AF367+2 -> 765.60001 | AH368: =AE368-W368 -> 97.666667
A369: 366 | B369: =A369*0.03 -> 10.98 | C369: =C368 -> 50 | D369: =D368 -> 300 | E369: =E368 -> 134.33333 | F369: =F368+1 -> 409.60001 | J369: 232 | K369: 399.60001 | P369: 218 | Q369: 394.60001 | T369: 172 | U369: 461.6 | W369: 177 | X369: 459.6 | Z369: 167 | AA369: 429.60001
A370: 367 | B370: =A370*0.03 -> 11.01 | C370: =C369 -> 50 | D370: =D369 -> 300 | E370: =E369 -> 134.33333 | F370: =F369+1 -> 410.60001 | J370: 233 | K370: 401.60001 | P370: 218 | Q370: 395.60001 | T370: 172 | U370: 461.6 | W370: 177 | X370: 460.6 | Z370: 167 | AA370: 429.60001
A371: 368 | B371: =A371*0.03 -> 11.04 | C371: =C370 -> 50 | D371: =D370 -> 300 | E371: =E370 -> 134.33333 | F371: =F370+1 -> 411.60001 | J371: 233 | K371: 402.60001 | P371: 218 | Q371: 397.60001 | T371: 172 | U371: 462.6 | W371: 177 | X371: 461.6 | Z371: 167 | AA371: 430.60001
A372: 369 | B372: =A372*0.03 -> 11.07 | C372: =C371 -> 50 | D372: =D371 -> 300 | E372: =E371 -> 134.33333 | F372: =F371+1 -> 412.60001 | J372: 233 | K372: 405.60001 | P372: 218 | Q372: 398.60001 | T372: 172 | U372: 463.6 | W372: 177 | X372: 461.6 | Z372: 167 | AA372: 432.60001
A373: 370 | B373: =A373*0.03 -> 11.1 | C373: =C372 -> 50 | D373: =D372 -> 300 | E373: =E372 -> 134.33333 | F373: =F372+1 -> 413.60001 | J373: 233 | K373: 406.60001 | P373: 218 | Q373: 400.60001 | T373: 172 | U373: 464.6 | W373: 177 | X373: 462.6 | Z373: 167 | AA373: 433.60001
A374: 371 | B374: =A374*0.03 -> 11.13 | C374: =C373 -> 50 | D374: =D373 -> 300 | E374: =E373 -> 134.33333 | F374: =F373+1 -> 414.60001 | J374: 233 | K374: 408.60001 | P374: 218 | Q374: 402.60001 | T374: 172 | U374: 465.6 | W374: 177 | X374: 463.6 | Z374: 167 | AA374: 435.60001
...

Sheet 30
G1: Max1 | H1: Max2 | I1: Max 3 | J1: Kiri | AG1: Max1 | AH1: Max2 | AI1: Max 3
G2: =MAX(G4:G485) -> 90.666667 | H2: =MAX(H4:H485) -> 92.666667 | I2: =MAX(I4:I485) -> 95.666667 | AG2: =MAX(AG4:AG485) -> 89.333333 | AH2: =MAX(AH4:AH485) -> 92.333333 | AI2: =MAX(AI4:AI485) -> 93.333333
B3: t | C3: gangg x | D3: gangg y | E3: Ux | F3: Uy | G3: Simpangan 1 | H3: Simpangan 2 | I3: Simpangan 3 | J3: x | K3: y | L3: z | T3: x | U3: y | V3: z | AC3: gangg x | AD3: gangg y | AE3: Ux | AF3: Uy | AG3: Simpangan 1 | AH3: Simpangan 2 | AI3: Simpangan 3
A4: 1 | B4: =A4*0.03 -> 0.03 | C4: =50 -> 50 | D4: 300 | E4: =AVERAGE(J4,M4,P4) -> 142.33333 | F4: =MIN(K4,N4,Q4) -> 42.600006 | G4: =J4-E4 -> -0.33333333 | H4: =M4-E4 -> -0.33333333 | I4: =P4-E4 -> 0.66666667 | J4: 142 | K4: 45.600006 | L4: a | M4: 142 | N4: 42.600006 | O4: b | P4: 143 | Q4: 45.600006 | R4: c | T4: 262 | U4: 22.600006 | V4: a | W4: 261 | X4: 36.600006 | Y4: b | Z4: 264 | AA4: 29.600006 | AB4: c | AC4: =350 -> 350 | AD4: 350 | AE4: =AVERAGE(T4,W4,Z4) -> 262.33333 | AF4: =MIN(U4,X4,AA4) -> 22.600006 | AG4: =AE4-T4 -> 0.33333333 | AH4: =AE4-W4 -> 1.3333333 | AI4: =AE4-Z4 -> -1.6666667
A5: 2 | B5: =A5*0.03 -> 0.06 | C5: =C4 -> 50 | D5: =D4 -> 300 | E5: =E4 -> 142.33333 | F5: =F4+1 -> 43.600006 | G5: =J5-E5 -> -0.33333333 | H5: =M5-E5 -> -0.33333333 | I5: =P5-E5 -> 0.66666667 | J5: 142 | K5: 46.600006 | L5: a | M5: 142 | N5: 43.600006 | O5: b | P5: 143 | Q5: 45.600006 | R5: c | T5: 262 | U5: 23.600006 | V5: a | W5: 261 | X5: 37.600006 | Y5: b | Z5: 264 | AA5: 29.600006 | AB5: c | AC5: =AC4 -> 350 | AD5: =AD4 -> 350 | AE5: =AE4 -> 262.33333 | AF5: =AF4+2 -> 24.600006 | AG5: =AE5-T5 -> 0.33333333 | AH5: =AE5-W5 -> 1.3333333 | AI5: =AE5-Z5 -> -1.6666667
A6: 3 | B6: =A6*0.03 -> 0.09 | C6: =C5 -> 50 | D6: =D5 -> 300 | E6: =E5 -> 142.33333 | F6: =F5+1 -> 44.600006 | G6: =J6-E6 -> -0.33333333 | H6: =M6-E6 -> -0.33333333 | I6: =P6-E6 -> 0.66666667 | J6: 142 | K6: 48.600006 | L6: a | M6: 142 | N6: 44.600006 | O6: b | P6: 143 | Q6: 46.600006 | R6: c | T6: 262 | U6: 24.600006 | V6: a | W6: 261 | X6: 37.600006 | Y6: b | Z6: 264 | AA6: 30.600006 | AB6: c | AC6: =AC5 -> 350 | AD6: =AD5 -> 350 | AE6: =AE5 -> 262.33333 | AF6: =AF5+2 -> 26.600006 | AG6: =AE6-T6 -> 0.33333333 | AH6: =AE6-W6 -> 1.3333333 | AI6: =AE6-Z6 -> -1.6666667
A7: 4 | B7: =A7*0.03 -> 0.12 | C7: =C6 -> 50 | D7: =D6 -> 300 | E7: =E6 -> 142.33333 | F7: =F6+1 -> 45.600006 | G7: =J7-E7 -> -0.33333333 | H7: =M7-E7 -> -0.33333333 | I7: =P7-E7 -> 0.66666667 | J7: 142 | K7: 49.600006 | L7: a | M7: 142 | N7: 45.600006 | O7: b | P7: 143 | Q7: 47.600006 | R7: c | T7: 262 | U7: 25.600006 | V7: a | W7: 261 | X7: 38.600006 | Y7: b | Z7: 264 | AA7: 33.600006 | AB7: c | AC7: =AC6 -> 350 | AD7: =AD6 -> 350 | AE7: =AE6 -> 262.33333 | AF7: =AF6+2 -> 28.600006 | AG7: =AE7-T7 -> 0.33333333 | AH7: =AE7-W7 -> 1.3333333 | AI7: =AE7-Z7 -> -1.6666667
A8: 5 | B8: =A8*0.03 -> 0.15 | C8: =C7 -> 50 | D8: =D7 -> 300 | E8: =E7 -> 142.33333 | F8: =F7+1 -> 46.600006 | G8: =J8-E8 -> -0.33333333 | H8: =M8-E8 -> -0.33333333 | I8: =P8-E8 -> 0.66666667 | J8: 142 | K8: 50.600006 | L8: a | M8: 142 | N8: 46.600006 | O8: b | P8: 143 | Q8: 48.600006 | R8: c | T8: 262 | U8: 25.600006 | V8: a | W8: 261 | X8: 39.600006 | Y8: b | Z8: 264 | AA8: 34.600006 | AB8: c | AC8: =AC7 -> 350 | AD8: =AD7 -> 350 | AE8: =AE7 -> 262.33333 | AF8: =AF7+2 -> 30.600006 | AG8: =AE8-T8 -> 0.33333333 | AH8: =AE8-W8 -> 1.3333333 | AI8: =AE8-Z8 -> -1.6666667
A9: 6 | B9: =A9*0.03 -> 0.18 | C9: =C8 -> 50 | D9: =D8 -> 300 | E9: =E8 -> 142.33333 | F9: =F8+1 -> 47.600006 | G9: =J9-E9 -> -0.33333333 | H9: =M9-E9 -> -0.33333333 | I9: =P9-E9 -> 0.66666667 | J9: 142 | K9: 52.600006 | L9: a | M9: 142 | N9: 47.600006 | O9: b | P9: 143 | Q9: 49.600006 | R9: c | T9: 262 | U9: 26.600006 | V9: a | W9: 261 | X9: 40.600006 | Y9: b | Z9: 264 | AA9: 36.600006 | AB9: c | AC9: =AC8 -> 350 | AD9: =AD8 -> 350 | AE9: =AE8 -> 262.33333 | AF9: =AF8+2 -> 32.600006 | AG9: =AE9-T9 -> 0.33333333 | AH9: =AE9-W9 -> 1.3333333 | AI9: =AE9-Z9 -> -1.6666667
A10: 7 | B10: =A10*0.03 -> 0.21 | C10: =C9 -> 50 | D10: =D9 -> 300 | E10: =E9 -> 142.33333 | F10: =F9+1 -> 48.600006 | G10: =J10-E10 -> -0.33333333 | H10: =M10-E10 -> -0.33333333 | I10: =P10-E10 -> 0.66666667 | J10: 142 | K10: 53.600006 | L10: a | M10: 142 | N10: 48.600006 | O10: b | P10: 143 | Q10: 49.600006 | R10: c | T10: 262 | U10: 27.600006 | V10: a | W10: 261 | X10: 41.600006 | Y10: b | Z10: 264 | AA10: 37.600006 | AB10: c | AC10: =AC9 -> 350 | AD10: =AD9 -> 350 | AE10: =AE9 -> 262.33333 | AF10: =AF9+2 -> 34.600006 | AG10: =AE10-T10 -> 0.33333333 | AH10: =AE10-W10 -> 1.3333333 | AI10: =AE10-Z10 -> -1.6666667
A11: 8 | B11: =A11*0.03 -> 0.24 | C11: =C10 -> 50 | D11: =D10 -> 300 | E11: =E10 -> 142.33333 | F11: =F10+1 -> 49.600006 | G11: =J11-E11 -> -0.33333333 | H11: =M11-E11 -> -0.33333333 | I11: =P11-E11 -> 0.66666667 | J11: 142 | K11: 55.600006 | L11: a | M11: 142 | N11: 49.600006 | O11: b | P11: 143 | Q11: 50.600006 | R11: c | T11: 262 | U11: 28.600006 | V11: a | W11: 261 | X11: 41.600006 | Y11: b | Z11: 264 | AA11: 40.600006 | AB11: c | AC11: =AC10 -> 350 | AD11: =AD10 -> 350 | AE11: =AE10 -> 262.33333 | AF11: =AF10+2 -> 36.600006 | AG11: =AE11-T11 -> 0.33333333 | AH11: =AE11-W11 -> 1.3333333 | AI11: =AE11-Z11 -> -1.6666667
A12: 9 | B12: =A12*0.03 -> 0.27 | C12: =C11 -> 50 | D12: =D11 -> 300 | E12: =E11 -> 142.33333 | F12: =F11+1 -> 50.600006 | G12: =J12-E12 -> -0.33333333 | H12: =M12-E12 -> -0.33333333 | I12: =P12-E12 -> 1.6666667 | J12: 142 | K12: 56.600006 | L12: a | M12: 142 | N12: 49.600006 | O12: b | P12: 144 | Q12: 50.600006 | R12: c | T12: 262 | U12: 29.600006 | V12: a | W12: 261 | X12: 42.600006 | Y12: b | Z12: 264 | AA12: 41.600006 | AB12: c | AC12: =AC11 -> 350 | AD12: =AD11 -> 350 | AE12: =AE11 -> 262.33333 | AF12: =AF11+2 -> 38.600006 | AG12: =AE12-T12 -> 0.33333333 | AH12: =AE12-W12 -> 1.3333333 | AI12: =AE12-Z12 -> -1.6666667
A13: 10 | B13: =A13*0.03 -> 0.3 | C13: =C12 -> 50 | D13: =D12 -> 300 | E13: =E12 -> 142.33333 | F13: =F12+1 -> 51.600006 | G13: =J13-E13 -> -0.33333333 | H13: =M13-E13 -> -0.33333333 | I13: =P13-E13 -> 1.6666667 | J13: 142 | K13: 57.600006 | L13: a | M13: 142 | N13: 50.600006 | O13: b | P13: 144 | Q13: 51.600006 | R13: c | T13: 262 | U13: 30.600006 | V13: a | W13: 261 | X13: 43.600006 | Y13: b | Z13: 264 | AA13: 43.600006 | AB13: c | AC13: =AC12 -> 350 | AD13: =AD12 -> 350 | AE13: =AE12 -> 262.33333 | AF13: =AF12+2 -> 40.600006 | AG13: =AE13-T13 -> 0.33333333 | AH13: =AE13-W13 -> 1.3333333 | AI13: =AE13-Z13 -> -1.6666667
A14: 11 | B14: =A14*0.03 -> 0.33 | C14: =C13 -> 50 | D14: =D13 -> 300 | E14: =E13 -> 142.33333 | F14: =F13+1 -> 52.600006 | G14: =J14-E14 -> -0.33333333 | H14: =M14-E14 -> -0.33333333 | I14: =P14-E14 -> 2.6666667 | J14: 142 | K14: 57.600006 | L14: a | M14: 142 | N14: 52.600006 | O14: b | P14: 145 | Q14: 52.600006 | R14: c | T14: 262 | U14: 31.600006 | V14: a | W14: 261 | X14: 44.600006 | Y14: b | Z14: 264 | AA14: 45.600006 | AB14: c | AC14: =AC13 -> 350 | AD14: =AD13 -> 350 | AE14: =AE13 -> 262.33333 | AF14: =AF13+2 -> 42.600006 | AG14: =AE14-T14 -> 0.33333333 | AH14: =AE14-W14 -> 1.3333333 | AI14: =AE14-Z14 -> -1.6666667
A15: 12 | B15: =A15*0.03 -> 0.36 | C15: =C14 -> 50 | D15: =D14 -> 300 | E15: =E14 -> 142.33333 | F15: =F14+1 -> 53.600006 | G15: =J15-E15 -> -0.33333333 | H15: =M15-E15 -> -0.33333333 | I15: =P15-E15 -> 2.6666667 | J15: 142 | K15: 58.600006 | L15: a | M15: 142 | N15: 53.600006 | O15: b | P15: 145 | Q15: 53.600006 | R15: c | T15: 262 | U15: 33.600006 | V15: a | W15: 261 | X15: 45.600006 | Y15: b | Z15: 264 | AA15: 46.600006 | AB15: c | AC15: =AC14 -> 350 | AD15: =AD14 -> 350 | AE15: =AE14 -> 262.33333 | AF15: =AF14+2 -> 44.600006 | AG15: =AE15-T15 -> 0.33333333 | AH15: =AE15-W15 -> 1.3333333 | AI15: =AE15-Z15 -> -1.6666667
A16: 13 | B16: =A16*0.03 -> 0.39 | C16: =C15 -> 50 | D16: =D15 -> 300 | E16: =E15 -> 142.33333 | F16: =F15+1 -> 54.600006 | G16: =J16-E16 -> -0.33333333 | H16: =M16-E16 -> -0.33333333 | I16: =P16-E16 -> 2.6666667 | J16: 142 | K16: 59.600006 | L16: a | M16: 142 | N16: 53.600006 | O16: b | P16: 145 | Q16: 53.600006 | R16: c | T16: 262 | U16: 33.600006 | V16: a | W16: 261 | X16: 47.600006 | Y16: b | Z16: 264 | AA16: 48.600006 | AB16: c | AC16: =AC15 -> 350 | AD16: =AD15 -> 350 | AE16: =AE15 -> 262.33333 | AF16: =AF15+2 -> 46.600006 | AG16: =AE16-T16 -> 0.33333333 | AH16: =AE16-W16 -> 1.3333333 | AI16: =AE16-Z16 -> -1.6666667
... A361: 358 | B361: =A361*0.03 -> 10.74 | C361: =C360 -> 50 | D361: =D360 -> 300 | E361: =E360 -> 142.33333 | F361: =F360+1 -> 399.60001 | G361: =J361-E361 -> 86.666667 | H361: =M361-E361 -> 89.666667 | I361: =P361-E361 -> 70.666667 | J361: 229 | K361: 466.6 | L361: a | M361: 232 | N361: 344.60001 | O361: b | P361: 213 | Q361: 472.6 | R361: c | T361: 196 | U361: 489.6 | V361: a | W361: 170 | X361: 479.6 | Y361: b | Z361: 209 | AA361: 488.6 | AB361: c | AC361: =AC360 -> 350 | AD361: =AD360 -> 350 | AE361: =AE360 -> 262.33333 | AF361: =AF360+2 -> 736.60001 | AG361: =AE361-T361 -> 66.333333 | AH361: =AE361-W361 -> 92.333333 | AI361: =AE361-Z361 -> 53.333333
A362: 359 | B362: =A362*0.03 -> 10.77 | C362: =C361 -> 50 | D362: =D361 -> 300 | E362: =E361 -> 142.33333 | F362: =F361+1 -> 400.60001 | G362: =J362-E362 -> 86.666667 | H362: =M362-E362 -> 89.666667 | I362: =P362-E362 -> 70.666667 | J362: 229 | K362: 468.6 | L362: a | M362: 232 | N362: 345.60001 | O362: b | P362: 213 | Q362: 473.6 | R362: c | T362: 196 | U362: 490.6 | V362: a | W362: 170 | X362: 480.6 | Y362: b | AC362: =AC361 -> 350 | AD362: =AD361 -> 350 | AE362: =AE361 -> 262.33333 | AF362: =AF361+2 -> 738.60001 | AG362: =AE362-T362 -> 66.333333 | AH362: =AE362-W362 -> 92.333333
A363: 360 | B363: =A363*0.03 -> 10.8 | C363: =C362 -> 50 | D363: =D362 -> 300 | E363: =E362 -> 142.33333 | F363: =F362+1 -> 401.60001 | G363: =J363-E363 -> 86.666667 | H363: =M363-E363 -> 89.666667 | I363: =P363-E363 -> 70.666667 | J363: 229 | K363: 469.6 | L363: a | M363: 232 | N363: 345.60001 | O363: b | P363: 213 | Q363: 473.6 | R363: c | T363: 196 | U363: 491.6 | V363: a | W363: 170 | X363: 481.6 | Y363: b | AC363: =AC362 -> 350 | AD363: =AD362 -> 350 | AE363: =AE362 -> 262.33333 | AF363: =AF362+2 -> 740.60001 | AG363: =AE363-T363 -> 66.333333 | AH363: =AE363-W363 -> 92.333333
A364: 361 | B364: =A364*0.03 -> 10.83 | C364: =C363 -> 50 | D364: =D363 -> 300 | E364: =E363 -> 142.33333 | F364: =F363+1 -> 402.60001 | G364: =J364-E364 -> 86.666667 | H364: =M364-E364 -> 89.666667 | I364: =P364-E364 -> 70.666667 | J364: 229 | K364: 470.6 | L364: a | M364: 232 | N364: 347.60001 | O364: b | P364: 213 | Q364: 474.6 | R364: c | T364: 196 | U364: 492.6 | V364: a | W364: 170 | X364: 481.6 | Y364: b | AC364: =AC363 -> 350 | AD364: =AD363 -> 350 | AE364: =AE363 -> 262.33333 | AF364: =AF363+2 -> 742.60001 | AG364: =AE364-T364 -> 66.333333 | AH364: =AE364-W364 -> 92.333333
A365: 362 | B365: =A365*0.03 -> 10.86 | C365: =C364 -> 50 | D365: =D364 -> 300 | E365: =E364 -> 142.33333 | F365: =F364+1 -> 403.60001 | G365: =J365-E365 -> 86.666667 | H365: =M365-E365 -> 89.666667 | I365: =P365-E365 -> 70.666667 | J365: 229 | K365: 471.6 | L365: a | M365: 232 | N365: 348.60001 | O365: b | P365: 213 | Q365: 475.6 | R365: c | T365: 196 | U365: 493.6 | V365: a | W365: 170 | X365: 482.6 | Y365: b | AC365: =AC364 -> 350 | AD365: =AD364 -> 350 | AE365: =AE364 -> 262.33333 | AF365: =AF364+2 -> 744.60001 | AG365: =AE365-T365 -> 66.333333 | AH365: =AE365-W365 -> 92.333333
A366: 363 | B366: =A366*0.03 -> 10.89 | C366: =C365 -> 50 | D366: =D365 -> 300 | E366: =E365 -> 142.33333 | F366: =F365+1 -> 404.60001 | G366: =J366-E366 -> 86.666667 | H366: =M366-E366 -> 90.666667 | I366: =P366-E366 -> 69.666667 | J366: 229 | K366: 473.6 | L366: a | M366: 233 | N366: 349.60001 | O366: b | P366: 212 | Q366: 475.6 | R366: c | T366: 196 | U366: 493.6 | V366: a | W366: 170 | X366: 483.6 | Y366: b | AC366: =AC365 -> 350 | AD366: =AD365 -> 350 | AE366: =AE365 -> 262.33333 | AF366: =AF365+2 -> 746.60001 | AG366: =AE366-T366 -> 66.333333 | AH366: =AE366-W366 -> 92.333333
A367: 364 | B367: =A367*0.03 -> 10.92 | C367: =C366 -> 50 | D367: =D366 -> 300 | E367: =E366 -> 142.33333 | F367: =F366+1 -> 405.60001 | G367: =J367-E367 -> 86.666667 | H367: =M367-E367 -> 90.666667 | I367: =P367-E367 -> 69.666667 | J367: 229 | K367: 473.6 | L367: a | M367: 233 | N367: 349.60001 | O367: b | P367: 212 | Q367: 476.6 | R367: c | W367: 170 | X367: 484.6 | Y367: b | AC367: =AC366 -> 350 | AD367: =AD366 -> 350 | AE367: =AE366 -> 262.33333 | AF367: =AF366+2 -> 748.60001 | AH367: =AE367-W367 -> 92.333333
A368: 365 | B368: =A368*0.03 -> 10.95 | C368: =C367 -> 50 | D368: =D367 -> 300 | E368: =E367 -> 142.33333 | F368: =F367+1 -> 406.60001 | G368: =J368-E368 -> 86.666667 | H368: =M368-E368 -> 90.666667 | J368: 229 | K368: 474.6 | L368: a | M368: 233 | N368: 350.60001 | O368: b | W368: 170 | X368: 485.6 | Y368: b | AC368: =AC367 -> 350 | AD368: =AD367 -> 350 | AE368: =AE367 -> 262.33333 | AF368: =AF367+2 -> 750.60001 | AH368: =AE368-W368 -> 92.333333
A369: 366 | B369: =A369*0.03 -> 10.98 | C369: =C368 -> 50 | D369: =D368 -> 300 | E369: =E368 -> 142.33333 | F369: =F368+1 -> 407.60001 | H369: =M369-E369 -> 90.666667 | M369: 233 | N369: 351.60001 | O369: b
A370: 367 | B370: =A370*0.03 -> 11.01 | C370: =C369 -> 50 | D370: =D369 -> 300 | E370: =E369 -> 142.33333 | F370: =F369+1 -> 408.60001 | H370: =M370-E370 -> 90.666667 | M370: 233 | N370: 352.60001 | O370: b
A371: 368 | B371: =A371*0.03 -> 11.04 | C371: =C370 -> 50 | D371: =D370 -> 300 | E371: =E370 -> 142.33333 | F371: =F370+1 -> 409.60001 | H371: =M371-E371 -> 90.666667 | M371: 233 | N371: 353.60001 | O371: b
A372: 369 | B372: =A372*0.03 -> 11.07 | C372: =C371 -> 50 | D372: =D371 -> 300 | E372: =E371 -> 142.33333 | F372: =F371+1 -> 410.60001 | H372: =M372-E372 -> 90.666667 | M372: 233 | N372: 353.60001 | O372: b
A373: 370 | B373: =A373*0.03 -> 11.1 | C373: =C372 -> 50 | D373: =D372 -> 300 | E373: =E372 -> 142.33333 | F373: =F372+1 -> 411.60001 | H373: =M373-E373 -> 90.666667 | M373: 233 | N373: 354.60001 | O373: b
A374: 371 | B374: =A374*0.03 -> 11.13 | C374: =C373 -> 50 | D374: =D373 -> 300 | E374: =E373 -> 142.33333 | F374: =F373+1 -> 412.60001 | H374: =M374-E374 -> 90.666667 | M374: 233 | N374: 355.60001 | O374: b
A375: 372 | B375: =A375*0.03 -> 11.16 | C375: =C374 -> 50 | D375: =D374 -> 300 | E375: =E374 -> 142.33333 | F375: =F374+1 -> 413.60001 | H375: =M375-E375 -> 90.666667 | M375: 233 | N375: 356.60001 | O375: b
A376: 373 | B376: =A376*0.03 -> 11.19 | C376: =C375 -> 50 | D376: =D375 -> 300 | E376: =E375 -> 142.33333 | F376: =F375+1 -> 414.60001 | H376: =M376-E376 -> 90.666667 | M376: 233 | N376: 357.60001 | O376: b
A377: 374 | B377: =A377*0.03 -> 11.22 | C377: =C376 -> 50 | D377: =D376 -> 300 | E377: =E376 -> 142.33333 | F377: =F376+1 -> 415.60001 | H377: =M377-E377 -> 90.666667 | M377: 233 | N377: 357.60001 | O377: b
A378: 375 | B378: =A378*0.03 -> 11.25 | C378: =C377 -> 50 | D378: =D377 -> 300 | E378: =E377 -> 142.33333 | F378: =F377+1 -> 416.60001 | H378: =M378-E378 -> 90.666667 | M378: 233 | N378: 358.60001 | O378: b
A379: 376 | B379: =A379*0.03 -> 11.28 | C379: =C378 -> 50 | D379: =D378 -> 300 | E379: =E378 -> 142.33333 | F379: =F378+1 -> 417.60001 | H379: =M379-E379 -> 91.666667 | M379: 234 | N379: 359.60001 | O379: b
A380: 377 | B380: =A380*0.03 -> 11.31 | C380: =C379 -> 50 | D380: =D379 -> 300 | E380: =E379 -> 142.33333 | F380: =F379+1 -> 418.60001 | H380: =M380-E380 -> 91.666667 | M380: 234 | N380: 360.60001 | O380: b
... A485: 482 | B485: =A485*0.03 -> 14.46 | C485: =C484 -> 50 | D485: =D484 -> 300 | E485: =E484 -> 142.33333 | F485: =F484+1 -> 523.60001 | H485: =M485-E485 -> 77.666667 | M485: 220 | N485: 473.6 | O485: b

Sheet 40
G1: Max1 | H1: Max2 | I1: Max 3 | J1: Kiri | AG1: Max1 | AH1: Max2 | AI1: Max 3
G2: =MAX(G4:G485) -> 71 | H2: =MAX(H4:H485) -> 68 | I2: =MAX(I4:I485) -> 72 | AG2: =MAX(AG4:AG485) -> 73.333333 | AH2: =MAX(AH4:AH485) -> 75.333333 | AI2: =MAX(AI4:AI485) -> 71.333333
B3: t | C3: gangg x | D3: gangg y | E3: Ux | F3: Uy | G3: Simpangan 1 | H3: Simpangan 2 | I3: Simpangan 3 | J3: x | K3: y | L3: z | T3: x | U3: y | V3: z | AC3: gangg x | AD3: gangg y | AE3: Ux | AF3: Uy | AG3: Simpangan 1 | AH3: Simpangan 2 | AI3: Simpangan 3
A4: 1 | B4: =A4*0.03 -> 0.03 | C4: =50 -> 50 | D4: 300 | E4: =AVERAGE(J4,M4,P4) -> 153 | F4: =MIN(K4,N4,Q4) -> 43.600006 | G4: =J4-E4 -> -2 | H4: =M4-E4 -> 0 | I4: =P4-E4 -> 2 | J4: 151 | K4: 44.600006 | L4: a | M4: 153 | N4: 43.600006 | O4: b | P4: 155 | Q4: 43.600006 | R4: c | T4: 253 | U4: 33.600006 | V4: a | W4: 250 | X4: 33.600006 | Y4: b | Z4: 254 | AA4: 33.600006 | AB4: c | AC4: =350 -> 350 | AD4: 300 | AE4: =AVERAGE(T4,W4,Z4) -> 252.33333 | AF4: =MIN(U4,X4,AA4) -> 33.600006 | AG4: =AE4-T4 -> -0.66666667 | AH4: =AE4-W4 -> 2.3333333 | AI4: =AE4-Z4 -> -1.6666667
A5: 2 | B5: =A5*0.03 -> 0.06 | C5: =C4 -> 50 | D5: =D4 -> 300 | E5: =E4 -> 153 | F5: =F4+1 -> 44.600006 | G5: =J5-E5 -> -2 | H5: =M5-E5 -> 0 | I5: =P5-E5 -> 2 | J5: 151 | K5: 45.600006 | L5: a | M5: 153 | N5: 45.600006 | O5: b | P5: 155 | Q5: 45.600006 | R5: c | T5: 253 | U5: 33.600006 | V5: a | W5: 250 | X5: 34.600006 | Y5: b | Z5: 254 | AA5: 34.600006 | AB5: c | AC5: =AC4 -> 350 | AD5: =AD4 -> 300 | AE5: =AE4 -> 252.33333 | AF5: =AF4+2 -> 35.600006 | AG5: =AE5-T5 -> -0.66666667 | AH5: =AE5-W5 -> 2.3333333 | AI5: =AE5-Z5 -> -1.6666667
A6: 3 | B6: =A6*0.03 -> 0.09 | C6: =C5 -> 50 | D6: =D5 -> 300 | E6: =E5 -> 153 | F6: =F5+1 -> 45.600006 | G6: =J6-E6 -> -2 | H6: =M6-E6 -> 0 | I6: =P6-E6 -> 2 | J6: 151 | K6: 45.600006 | L6: a | M6: 153 | N6: 45.600006 | O6: b | P6: 155 | Q6: 48.600006 | R6: c | T6: 253 | U6: 35.600006 | V6: a | W6: 250 | X6: 35.600006 | Y6: b | Z6: 254 | AA6: 36.600006 | AB6: c | AC6: =AC5 -> 350 | AD6: =AD5 -> 300 | AE6: =AE5 -> 252.33333 | AF6: =AF5+2 -> 37.600006 | AG6: =AE6-T6 -> -0.66666667 | AH6: =AE6-W6 -> 2.3333333 | AI6: =AE6-Z6 -> -1.6666667
A7: 4 | B7: =A7*0.03 -> 0.12 | C7: =C6 -> 50 | D7: =D6 -> 300 | E7: =E6 -> 153 | F7: =F6+1 -> 46.600006 | G7: =J7-E7 -> -1 | H7: =M7-E7 -> 0 | I7: =P7-E7 -> 1 | J7: 152 | K7: 46.600006 | L7: a | M7: 153 | N7: 46.600006 | O7: b | P7: 154 | Q7: 51.600006 | R7: c | T7: 253 | U7: 37.600006 | V7: a | W7: 250 | X7: 37.600006 | Y7: b | Z7: 254 | AA7: 37.600006 | AB7: c | AC7: =AC6 -> 350 | AD7: =AD6 -> 300 | AE7: =AE6 -> 252.33333 | AF7: =AF6+2 -> 39.600006 | AG7: =AE7-T7 -> -0.66666667 | AH7: =AE7-W7 -> 2.3333333 | AI7: =AE7-Z7 -> -1.6666667
A8: 5 | B8: =A8*0.03 -> 0.15 | C8: =C7 -> 50 | D8: =D7 -> 300 | E8: =E7 -> 153 | F8: =F7+1 -> 47.600006 | G8: =J8-E8 -> -1 | H8: =M8-E8 -> 0 | I8: =P8-E8 -> 1 | J8: 152 | K8: 47.600006 | L8: a | M8: 153 | N8: 47.600006 | O8: b | P8: 154 | Q8: 53.600006 | R8: c | T8: 253 | U8: 39.600006 | V8: a | W8: 250 | X8: 37.600006 | Y8: b | Z8: 254 | AA8: 37.600006 | AB8: c | AC8: =AC7 -> 350 | AD8: =AD7 -> 300 | AE8: =AE7 -> 252.33333 | AF8: =AF7+2 -> 41.600006 | AG8: =AE8-T8 -> -0.66666667 | AH8: =AE8-W8 -> 2.3333333 | AI8: =AE8-Z8 -> -1.6666667
A9: 6 | B9: =A9*0.03 -> 0.18 | C9: =C8 -> 50 | D9: =D8 -> 300 | E9: =E8 -> 153 | F9: =F8+1 -> 48.600006 | G9: =J9-E9 -> -1 | H9: =M9-E9 -> 0 | I9: =P9-E9 -> 1 | J9: 152 | K9: 48.600006 | L9: a | M9: 153 | N9: 48.600006 | O9: b | P9: 154 | Q9: 54.600006 | R9: c | T9: 253 | U9: 40.600006 | V9: a | W9: 250 | X9: 40.600006 | Y9: b | Z9: 254 | AA9: 38.600006 | AB9: c | AC9: =AC8 -> 350 | AD9: =AD8 -> 300 | AE9: =AE8 -> 252.33333 | AF9: =AF8+2 -> 43.600006 | AG9: =AE9-T9 -> -0.66666667 | AH9: =AE9-W9 -> 2.3333333 | AI9: =AE9-Z9 -> -1.6666667
A10: 7 | B10: =A10*0.03 -> 0.21 | C10: =C9 -> 50 | D10: =D9 -> 300 | E10: =E9 -> 153 | F10: =F9+1 -> 49.600006 | G10: =J10-E10 -> -1 | H10: =M10-E10 -> 0 | I10: =P10-E10 -> 1 | J10: 152 | K10: 49.600006 | L10: a | M10: 153 | N10: 49.600006 | O10: b | P10: 154 | Q10: 56.600006 | R10: c | T10: 253 | U10: 42.600006 | V10: a | W10: 250 | X10: 41.600006 | Y10: b | Z10: 254 | AA10: 40.600006 | AB10: c | AC10: =AC9 -> 350 | AD10: =AD9 -> 300 | AE10: =AE9 -> 252.33333 | AF10: =AF9+2 -> 45.600006 | AG10: =AE10-T10 -> -0.66666667 | AH10: =AE10-W10 -> 2.3333333 | AI10: =AE10-Z10 -> -1.6666667
A11: 8 | B11: =A11*0.03 -> 0.24 | C11: =C10 -> 50 | D11: =D10 -> 300 | E11: =E10 -> 153 | F11: =F10+1 -> 50.600006 | G11: =J11-E11 -> -1 | H11: =M11-E11 -> 0 | I11: =P11-E11 -> 1 | J11: 152 | K11: 49.600006 | L11: a | M11: 153 | N11: 49.600006 | O11: b | P11: 154 | Q11: 57.600006 | R11: c | T11: 253 | U11: 45.600006 | V11: a | W11: 250 | X11: 42.600006 | Y11: b | Z11: 254 | AA11: 41.600006 | AB11: c | AC11: =AC10 -> 350 | AD11: =AD10 -> 300 | AE11: =AE10 -> 252.33333 | AF11: =AF10+2 -> 47.600006 | AG11: =AE11-T11 -> -0.66666667 | AH11: =AE11-W11 -> 2.3333333 | AI11: =AE11-Z11 -> -1.6666667
A12: 9 | B12: =A12*0.03 -> 0.27 | C12: =C11 -> 50 | D12: =D11 -> 300 | E12: =E11 -> 153 | F12: =F11+1 -> 51.600006 | G12: =J12-E12 -> -1 | H12: =M12-E12 -> 0 | I12: =P12-E12 -> 1 | J12: 152 | K12: 50.600006 | L12: a | M12: 153 | N12: 50.600006 | O12: b | P12: 154 | Q12: 58.600006 | R12: c | T12: 254 | U12: 45.600006 | V12: a | W12: 250 | X12: 43.600006 | Y12: b | Z12: 254 | AA12: 41.600006 | AB12: c | AC12: =AC11 -> 350 | AD12: =AD11 -> 300 | AE12: =AE11 -> 252.33333 | AF12: =AF11+2 -> 49.600006 | AG12: =AE12-T12 -> -1.6666667 | AH12: =AE12-W12 -> 2.3333333 | AI12: =AE12-Z12 -> -1.6666667
A13: 10 | B13: =A13*0.03 -> 0.3 | C13: =C12 -> 50 | D13: =D12 -> 300 | E13: =E12 -> 153 | F13: =F12+1 -> 52.600006 | G13: =J13-E13 -> 0 | H13: =M13-E13 -> 0 | I13: =P13-E13 -> 0 | J13: 153 | K13: 51.600006 | L13: a | M13: 153 | N13: 51.600006 | O13: b | P13: 153 | Q13: 60.600006 | R13: c | T13: 254 | U13: 46.600006 | V13: a | W13: 250 | X13: 44.600006 | Y13: b | Z13: 255 | AA13: 44.600006 | AB13: c | AC13: =AC12 -> 350 | AD13: =AD12 -> 300 | AE13: =AE12 -> 252.33333 | AF13: =AF12+2 -> 51.600006 | AG13: =AE13-T13 -> -1.6666667 | AH13: =AE13-W13 -> 2.3333333 | AI13: =AE13-Z13 -> -2.6666667
A14: 11 | B14: =A14*0.03 -> 0.33 | C14: =C13 -> 50 | D14: =D13 -> 300 | E14: =E13 -> 153 | F14: =F13+1 -> 53.600006 | G14: =J14-E14 -> 0 | H14: =M14-E14 -> 0 | I14: =P14-E14 -> 0 | J14: 153 | K14: 52.600006 | L14: a | M14: 153 | N14: 52.600006 | O14: b | P14: 153 | Q14: 61.600006 | R14: c | T14: 254 | U14: 47.600006 | V14: a | W14: 250 | X14: 45.600006 | Y14: b | Z14: 256 | AA14: 46.600006 | AB14: c | AC14: =AC13 -> 350 | AD14: =AD13 -> 300 | AE14: =AE13 -> 252.33333 | AF14: =AF13+2 -> 53.600006 | AG14: =AE14-T14 -> -1.6666667 | AH14: =AE14-W14 -> 2.3333333 | AI14: =AE14-Z14 -> -3.6666667
A15: 12 | B15: =A15*0.03 -> 0.36 | C15: =C14 -> 50 | D15: =D14 -> 300 | E15: =E14 -> 153 | F15: =F14+1 -> 54.600006 | G15: =J15-E15 -> 0 | H15: =M15-E15 -> 0 | I15: =P15-E15 -> 0 | J15: 153 | K15: 53.600006 | L15: a | M15: 153 | N15: 53.600006 | O15: b | P15: 153 | Q15: 62.600006 | R15: c | T15: 254 | U15: 48.600006 | V15: a | W15: 250 | X15: 45.600006 | Y15: b | Z15: 256 | AA15: 47.600006 | AB15: c | AC15: =AC14 -> 350 | AD15: =AD14 -> 300 | AE15: =AE14 -> 252.33333 | AF15: =AF14+2 -> 55.600006 | AG15: =AE15-T15 -> -1.6666667 | AH15: =AE15-W15 -> 2.3333333 | AI15: =AE15-Z15 -> -3.6666667
A16: 13 | B16: =A16*0.03 -> 0.39 | C16: =C15 -> 50 | D16: =D15 -> 300 | E16: =E15 -> 153 | F16: =F15+1 -> 55.600006 | G16: =J16-E16 -> 0 | H16: =M16-E16 -> 0 | I16: =P16-E16 -> 0 | J16: 153 | K16: 54.600006 | L16: a | M16: 153 | N16: 53.600006 | O16: b | P16: 153 | Q16: 64.600006 | R16: c | T16: 254 | U16: 49.600006 | V16: a | W16: 250 | X16: 46.600006 | Y16: b | Z16: 257 | AA16: 49.600006 | AB16: c | AC16: =AC15 -> 350 | AD16: =AD15 -> 300 | AE16: =AE15 -> 252.33333 | AF16: =AF15+2 -> 57.600006 | AG16: =AE16-T16 -> -1.6666667 | AH16: =AE16-W16 -> 2.3333333 | AI16: =AE16-Z16 -> -4.6666667
... A361: 358 | B361: =A361*0.03 -> 10.74 | C361: =C360 -> 50 | D361: =D360 -> 300 | E361: =E360 -> 153 | F361: =F360+1 -> 400.60001 | G361: =J361-E361 -> 64 | H361: =M361-E361 -> 49 | I361: =P361-E361 -> 72 | J361: 217 | K361: 416.60001 | L361: a | M361: 202 | N361: 416.60001 | O361: b | P361: 225 | Q361: 414.60001 | R361: c | T361: 206 | U361: 451.6 | V361: a | W361: 179 | X361: 333.60001 | Y361: b | Z361: 193 | AA361: 460.6 | AB361: c | AC361: =AC360 -> 350 | AD361: =AD360 -> 300 | AE361: =AE360 -> 252.33333 | AF361: =AF360+2 -> 747.60001 | AG361: =AE361-T361 -> 46.333333 | AH361: =AE361-W361 -> 73.333333 | AI361: =AE361-Z361 -> 59.333333
A362: 359 | B362: =A362*0.03 -> 10.77 | C362: =C361 -> 50 | D362: =D361 -> 300 | E362: =E361 -> 153 | F362: =F361+1 -> 401.60001 | G362: =J362-E362 -> 64 | H362: =M362-E362 -> 49 | I362: =P362-E362 -> 72 | J362: 217 | K362: 417.60001 | L362: a | M362: 202 | N362: 417.60001 | O362: b | P362: 225 | Q362: 417.60001 | R362: c | T362: 206 | U362: 453.6 | V362: a | W362: 179 | X362: 337.60001 | Y362: b | Z362: 193 | AA362: 461.6 | AB362: c | AC362: =AC361 -> 350 | AD362: =AD361 -> 300 | AE362: =AE361 -> 252.33333 | AF362: =AF361+2 -> 749.60001 | AG362: =AE362-T362 -> 46.333333 | AH362: =AE362-W362 -> 73.333333
A363: 360 | B363: =A363*0.03 -> 10.8 | C363: =C362 -> 50 | D363: =D362 -> 300 | E363: =E362 -> 153 | F363: =F362+1 -> 402.60001 | G363: =J363-E363 -> 63 | H363: =M363-E363 -> 49 | I363: =P363-E363 -> 72 | J363: 216 | K363: 418.60001 | L363: a | M363: 202 | N363: 417.60001 | O363: b | P363: 225 | Q363: 417.60001 | R363: c | T363: 206 | U363: 454.6 | V363: a | W363: 179 | X363: 341.60001 | Y363: b | Z363: 193 | AA363: 461.6 | AB363: c | AC363: =AC362 -> 350 | AD363: =AD362 -> 300 | AE363: =AE362 -> 252.33333 | AF363: =AF362+2 -> 751.60001 | AG363: =AE363-T363 -> 46.333333 | AH363: =AE363-W363 -> 73.333333
A364: 361 | B364: =A364*0.03 -> 10.83 | C364: =C363 -> 50 | D364: =D363 -> 300 | E364: =E363 -> 153 | F364: =F363+1 -> 403.60001 | G364: =J364-E364 -> 63 | H364: =M364-E364 -> 49 | I364: =P364-E364 -> 72 | J364: 216 | K364: 420.60001 | L364: a | M364: 202 | N364: 418.60001 | O364: b | P364: 225 | Q364: 418.60001 | R364: c | T364: 207 | U364: 456.6 | V364: a | W364: 179 | X364: 346.60001 | Y364: b | Z364: 193 | AA364: 462.6 | AB364: c | AC364: =AC363 -> 350 | AD364: =AD363 -> 300 | AE364: =AE363 -> 252.33333 | AF364: =AF363+2 -> 753.60001 | AG364: =AE364-T364 -> 45.333333 | AH364: =AE364-W364 -> 73.333333
A365: 362 | B365: =A365*0.03 -> 10.86 | C365: =C364 -> 50 | D365: =D364 -> 300 | E365: =E364 -> 153 | F365: =F364+1 -> 404.60001 | G365: =J365-E365 -> 62 | H365: =M365-E365 -> 49 | I365: =P365-E365 -> 72 | J365: 215 | K365: 421.60001 | L365: a | M365: 202 | N365: 420.60001 | O365: b | P365: 225 | Q365: 419.60001 | R365: c | T365: 207 | U365: 457.6 | V365: a | W365: 179 | X365: 351.60001 | Y365: b | Z365: 193 | AA365: 463.6 | AB365: c | AC365: =AC364 -> 350 | AD365: =AD364 -> 300 | AE365: =AE364 -> 252.33333 | AF365: =AF364+2 -> 755.60001 | AG365: =AE365-T365 -> 45.333333 | AH365: =AE365-W365 -> 73.333333
A366: 363 | B366: =A366*0.03 -> 10.89 | C366: =C365 -> 50 | D366: =D365 -> 300 | E366: =E365 -> 153 | F366: =F365+1 -> 405.60001 | G366: =J366-E366 -> 61 | H366: =M366-E366 -> 49 | I366: =P366-E366 -> 72 | J366: 214 | K366: 422.60001 | L366: a | M366: 202 | N366: 421.60001 | O366: b | P366: 225 | Q366: 421.60001 | R366: c | T366: 208 | U366: 459.6 | V366: a | W366: 179 | X366: 354.60001 | Y366: b | Z366: 193 | AA366: 464.6 | AB366: c | AC366: =AC365 -> 350 | AD366: =AD365 -> 300 | AE366: =AE365 -> 252.33333 | AF366: =AF365+2 -> 757.60001 | AG366: =AE366-T366 -> 44.333333 | AH366: =AE366-W366 -> 73.333333
A367: 364 | B367: =A367*0.03 -> 10.92 | C367: =C366 -> 50 | D367: =D366 -> 300 | E367: =E366 -> 153 | F367: =F366+1 -> 406.60001 | G367: =J367-E367 -> 60 | H367: =M367-E367 -> 49 | I367: =P367-E367 -> 72 | J367: 213 | K367: 423.60001 | L367: a | M367: 202 | N367: 421.60001 | O367: b | P367: 225 | Q367: 421.60001 | R367: c | T367: 209 | U367: 461.6 | V367: a | W367: 179 | X367: 357.60001 | Y367: b | Z367: 193 | AA367: 465.6 | AB367: c | AC367: =AC366 -> 350 | AD367: =AD366 -> 300 | AE367: =AE366 -> 252.33333 | AF367: =AF366+2 -> 759.60001 | AH367: =AE367-W367 -> 73.333333
A368: 365 | B368: =A368*0.03 -> 10.95 | C368: =C367 -> 50 | D368: =D367 -> 300 | E368: =E367 -> 153 | F368: =F367+1 -> 407.60001 | G368: =J368-E368 -> 60 | H368: =M368-E368 -> 49 | J368: 213 | K368: 424.60001 | L368: a | M368: 202 | N368: 422.60001 | O368: b | P368: 225 | Q368: 422.60001 | R368: c | T368: 209 | U368: 463.6 | V368: a | W368: 179 | X368: 359.60001 | Y368: b | Z368: 193 | AA368: 465.6 | AB368: c | AC368: =AC367 -> 350 | AD368: =AD367 -> 300 | AE368: =AE367 -> 252.33333 | AF368: =AF367+2 -> 761.60001 | AH368: =AE368-W368 -> 73.333333
A369: 366 | B369: =A369*0.03 -> 10.98 | C369: =C368 -> 50 | D369: =D368 -> 300 | E369: =E368 -> 153 | F369: =F368+1 -> 408.60001 | H369: =M369-E369 -> 49 | J369: 213 | K369: 425.60001 | L369: a | M369: 202 | N369: 423.60001 | O369: b | P369: 224 | Q369: 423.60001 | R369: c | T369: 210 | U369: 465.6 | V369: a | W369: 179 | X369: 361.60001 | Y369: b | Z369: 193 | AA369: 466.6 | AB369: c
A370: 367 | B370: =A370*0.03 -> 11.01 | C370: =C369 -> 50 | D370: =D369 -> 300 | E370: =E369 -> 153 | F370: =F369+1 -> 409.60001 | H370: =M370-E370 -> 49 | J370: 212 | K370: 425.60001 | L370: a | M370: 202 | N370: 425.60001 | O370: b | P370: 224 | Q370: 424.60001 | R370: c | T370: 211 | U370: 467.6 | V370: a | W370: 179 | X370: 362.60001 | Y370: b | Z370: 193 | AA370: 466.6 | AB370: c
A371: 368 | B371: =A371*0.03 -> 11.04 | C371: =C370 -> 50 | D371: =D370 -> 300 | E371: =E370 -> 153 | F371: =F370+1 -> 410.60001 | H371: =M371-E371 -> 50 | J371: 212 | K371: 426.60001 | L371: a | M371: 203 | N371: 425.60001 | O371: b | P371: 224 | Q371: 425.60001 | R371: c | T371: 212 | U371: 469.6 | V371: a | W371: 179 | X371: 364.60001 | Y371: b | Z371: 193 | AA371: 467.6 | AB371: c
A372: 369 | B372: =A372*0.03 -> 11.07 | C372: =C371 -> 50 | D372: =D371 -> 300 | E372: =E371 -> 153 | F372: =F371+1 -> 411.60001 | H372: =M372-E372 -> 50 | J372: 212 | K372: 427.60001 | L372: a | M372: 203 | N372: 426.60001 | O372: b | P372: 224 | Q372: 426.60001 | R372: c | T372: 213 | U372: 472.6 | V372: a | W372: 179 | X372: 365.60001 | Y372: b | Z372: 193 | AA372: 468.6 | AB372: c
A373: 370 | B373: =A373*0.03 -> 11.1 | C373: =C372 -> 50 | D373: =D372 -> 300 | E373: =E372 -> 153 | F373: =F372+1 -> 412.60001 | H373: =M373-E373 -> 50 | J373: 211 | K373: 427.60001 | L373: a | M373: 203 | N373: 427.60001 | O373: b | P373: 224 | Q373: 427.60001 | R373: c | T373: 213 | U373: 474.6 | V373: a | W373: 179 | X373: 366.60001 | Y373: b | Z373: 193 | AA373: 469.6 | AB373: c
A374: 371 | B374: =A374*0.03 -> 11.13 | C374: =C373 -> 50 | D374: =D373 -> 300 | E374: =E373 -> 153 | F374: =F373+1 -> 413.60001 | H374: =M374-E374 -> 50 | J374: 211 | K374: 428.60001 | L374: a | M374: 203 | N374: 429.60001 | O374: b | P374: 223 | Q374: 427.60001 | R374: c | T374: 213 | U374: 476.6 | V374: a | W374: 179 | X374: 368.60001 | Y374: b | Z374: 193 | AA374: 469.6 | AB374: c
A375: 372 | B375: =A375*0.03 -> 11.16 | C375: =C374 -> 50 | D375: =D374 -> 300 | E375: =E374 -> 153 | F375: =F374+1 -> 414.60001 | H375: =M375-E375 -> 50 | J375: 210 | K375: 429.60001 | L375: a | M375: 203 | N375: 430.60001 | O375: b | P375: 223 | Q375: 429.60001 | R375: c | T375: 214 | U375: 477.6 | V375: a | W375: 179 | X375: 369.60001 | Y375: b | Z375: 193 | AA375: 470.6 | AB375: c
A376: 373 | B376: =A376*0.03 -> 11.19 | C376: =C375 -> 50 | D376: =D375 -> 300 | E376: =E375 -> 153 | F376: =F375+1 -> 415.60001 | H376: =M376-E376 -> 51 | J376: 210 | K376: 429.60001 | L376: a | M376: 204 | N376: 431.60001 | O376: b | P376: 222 | Q376: 429.60001 | R376: c | T376: 214 | U376: 479.6 | V376: a | W376: 179 | X376: 369.60001 | Y376: b | Z376: 192 | AA376: 470.6 | AB376: c
A377: 374 | B377: =A377*0.03 -> 11.22 | C377: =C376 -> 50 | D377: =D376 -> 300 | E377: =E376 -> 153 | F377: =F376+1 -> 416.60001 | H377: =M377-E377 -> 51 | J377: 210 | K377: 430.60001 | L377: a | M377: 204 | N377: 433.60001 | O377: b | P377: 222 | Q377: 430.60001 | R377: c | T377: 214 | U377: 480.6 | V377: a | W377: 179 | X377: 371.60001 | Y377: b | Z377: 191 | AA377: 471.6 | AB377: c
A378: 375 | B378: =A378*0.03 -> 11.25 | C378: =C377 -> 50 | D378: =D377 -> 300 | E378: =E377 -> 153 | F378: =F377+1 -> 417.60001 | H378: =M378-E378 -> 51 | J378: 209 | K378: 431.60001 | L378: a | M378: 204 | N378: 433.60001 | O378: b | P378: 222 | Q378: 432.60001 | R378: c | T378: 214 | U378: 481.6 | V378: a | W378: 179 | X378: 373.60001 | Y378: b | Z378: 191 | AA378: 472.6 | AB378: c
A379: 376 | B379: =A379*0.03 -> 11.28 | C379: =C378 -> 50 | D379: =D378 -> 300 | E379: =E378 -> 153 | F379: =F378+1 -> 418.60001 | H379: =M379-E379 -> 51 | J379: 209 | K379: 433.60001 | L379: a | M379: 204 | N379: 434.60001 | O379: b | P379: 222 | Q379: 433.60001 | R379: c | T379: 214 | U379: 481.6 | V379: a | W379: 179 | X379: 373.60001 | Y379: b | Z379: 191 | AA379: 473.6 | AB379: c
A380: 377 | B380: =A380*0.03 -> 11.31 | C380: =C379 -> 50 | D380: =D379 -> 300 | E380: =E379 -> 153 | F380: =F379+1 -> 419.60001 | H380: =M380-E380 -> 51 | J380: 209 | K380: 433.60001 | L380: a | M380: 204 | N380: 435.60001 | O380: b | P380: 221 | Q380: 434.60001 | R380: c | T380: 214 | U380: 482.6 | V380: a | W380: 179 | X380: 374.60001 | Y380: b | Z380: 191 | AA380: 473.6 | AB380: c
... A387: 384 | B387: =A387*0.03 -> 11.52 | C387: =C386 -> 50 | D387: =D386 -> 300 | E387: =E386 -> 153 | F387: =F386+1 -> 426.60001 | H387: =M387-E387 -> 52 | J387: 209 | K387: 442.6 | L387: a | M387: 205 | N387: 445.6 | O387: b | P387: 221 | Q387: 443.6 | R387: c | T387: 214 | U387: 488.6 | V387: a | W387: 179 | X387: 380.60001 | Y387: b | Z387: 186 | AA387: 480.6 | AB387: c
